[2024-03-25T18:55:19.721+0000] {taskinstance.py:1979} INFO - Dependencies all met for dep_context=non-requeueable deps ti=<TaskInstance: loan_prediction.bash_task manual__2024-03-25T18:55:18.024063+00:00 [queued]>
[2024-03-25T18:55:19.726+0000] {taskinstance.py:1979} INFO - Dependencies all met for dep_context=requeueable deps ti=<TaskInstance: loan_prediction.bash_task manual__2024-03-25T18:55:18.024063+00:00 [queued]>
[2024-03-25T18:55:19.726+0000] {taskinstance.py:2193} INFO - Starting attempt 1 of 2
[2024-03-25T18:55:19.733+0000] {taskinstance.py:2217} INFO - Executing <Task(BashOperator): bash_task> on 2024-03-25 18:55:18.024063+00:00
[2024-03-25T18:55:19.741+0000] {standard_task_runner.py:60} INFO - Started process 85 to run task
[2024-03-25T18:55:19.743+0000] {standard_task_runner.py:87} INFO - Running: ['***', 'tasks', 'run', 'loan_prediction', 'bash_task', 'manual__2024-03-25T18:55:18.024063+00:00', '--job-id', '3', '--raw', '--subdir', 'DAGS_FOLDER/dag.py', '--cfg-path', '/tmp/tmp9qacp43v']
[2024-03-25T18:55:19.745+0000] {standard_task_runner.py:88} INFO - Job 3: Subtask bash_task
[2024-03-25T18:55:19.774+0000] {task_command.py:423} INFO - Running <TaskInstance: loan_prediction.bash_task manual__2024-03-25T18:55:18.024063+00:00 [running]> on host f892015b3bee
[2024-03-25T18:55:19.820+0000] {taskinstance.py:2513} INFO - Exporting env vars: AIRFLOW_CTX_DAG_OWNER='***' AIRFLOW_CTX_DAG_ID='loan_prediction' AIRFLOW_CTX_TASK_ID='bash_task' AIRFLOW_CTX_EXECUTION_DATE='2024-03-25T18:55:18.024063+00:00' AIRFLOW_CTX_TRY_NUMBER='1' AIRFLOW_CTX_DAG_RUN_ID='manual__2024-03-25T18:55:18.024063+00:00'
[2024-03-25T18:55:19.821+0000] {subprocess.py:63} INFO - Tmp dir root location: /tmp
[2024-03-25T18:55:19.821+0000] {subprocess.py:75} INFO - Running command: ['/usr/bin/bash', '-c', 'echo \nЗапуск ML моделей для предсказания по новым данным']
[2024-03-25T18:55:19.836+0000] {subprocess.py:86} INFO - Output:
[2024-03-25T18:55:19.838+0000] {subprocess.py:93} INFO - 
[2024-03-25T18:55:19.838+0000] {subprocess.py:93} INFO - /usr/bin/bash: line 2: Запуск: command not found
[2024-03-25T18:55:19.838+0000] {subprocess.py:97} INFO - Command exited with return code 127
[2024-03-25T18:55:19.846+0000] {taskinstance.py:2731} ERROR - Task failed with exception
Traceback (most recent call last):
  File "/home/airflow/.local/lib/python3.8/site-packages/airflow/models/taskinstance.py", line 444, in _execute_task
    result = _execute_callable(context=context, **execute_callable_kwargs)
  File "/home/airflow/.local/lib/python3.8/site-packages/airflow/models/taskinstance.py", line 414, in _execute_callable
    return execute_callable(context=context, **execute_callable_kwargs)
  File "/home/airflow/.local/lib/python3.8/site-packages/airflow/operators/bash.py", line 212, in execute
    raise AirflowException(
airflow.exceptions.AirflowException: Bash command failed. The command returned a non-zero exit code 127.
[2024-03-25T18:55:19.848+0000] {taskinstance.py:1149} INFO - Marking task as UP_FOR_RETRY. dag_id=loan_prediction, task_id=bash_task, execution_date=20240325T185518, start_date=20240325T185519, end_date=20240325T185519
[2024-03-25T18:55:19.855+0000] {standard_task_runner.py:107} ERROR - Failed to execute job 3 for task bash_task (Bash command failed. The command returned a non-zero exit code 127.; 85)
[2024-03-25T18:55:19.875+0000] {local_task_job_runner.py:234} INFO - Task exited with return code 1
[2024-03-25T18:55:19.893+0000] {taskinstance.py:3312} INFO - 0 downstream tasks scheduled from follow-on schedule check
