[2024-03-25T17:12:05.132+0000] {scheduler_job_runner.py:781} ERROR - Executor reports task instance <TaskInstance: loan_prediction.run_ML_models scheduled__2024-01-10T15:00:00+00:00 [queued]> finished (failed) although the task says it's queued. (Info: None) Was the task killed externally?
